Workbook

Sheet README
A1: MCAS · MASTER COURSE WORKBOOK
A2: Master Course Workbook
A4: A faculty-facing course-architecture tracker. Built to feed the MCAS Master Course Builder.
A6: How to use this workbook:
A7: 1. Start on tab 01 Course Information. One row per course you teach.
A8: 2. Add your course code(s) on the hidden Lookups tab (column 'Courses') so dropdowns work.
A9: 3. Complete tab 02 Faculty Brand Sheet so AI tools can match your voice and pedagogy.
A10: 4. Write your Learning Outcomes (tab 03). These anchor everything else.
A11: 5. Populate tab 04 Asset Capture as you collect videos, readings, tools, rubrics. Paste links.
A12: 6. Build out modules (06), schedule (05), assessments (07), engagement (08).
A13: 7. Run accessibility (09), RSI (10), and QA (11) before you launch (12).
A15: The Course Overview tab gives you a live dashboard: total assets, % with URLs, status counts.
... A25: Designed by MedMasters Collaborative. Use it, fork it, make it yours.

Sheet 00 Course Overview
A1: MCAS · DASHBOARD
A2: Course Overview
A3: Live counts pull from your other tabs. Edit data there, not here.
A5: TOTAL COURSES | B5: TOTAL ASSETS | C5: ASSETS WITH URL | D5: PERCENT WITH URL | E5: TOTAL OUTCOMES | F5: TOTAL MODULES | G5: TOTAL ASSESSMENTS | H5: RSI ENTRIES
A6: =COUNTA('01 Course Information'!B6:B500) -> 1 | B6: =COUNTA('04 Asset Capture'!A7:A1000) -> 0 | C6: =COUNTA('04 Asset Capture'!G7:G1000) -> 0 | D6: =IFERROR(COUNTA('04 Asset Capture'!G7:G1000)/COUNTA('04 Asset Capture'!A7:A1000),0) -> 0 | E6: =COUNTA('03 Learning Outcomes'!A7:A1000) -> 0 | F6: =COUNTA('06 Module Builder'!A7:A1000) -> 0 | G6: =COUNTA('07 Assessments'!A7:A1000) -> 0 | H6: =COUNTA('10 RSI'!A7:A1000) -> 0
A9: ASSET STATUS BREAKDOWN | D9: ACCESSIBILITY STATUS
A10: Planned | B10: =COUNTIF('04 Asset Capture'!T7:T1000,"Planned") -> 0 | D10: Pass | E10: =COUNTIF('04 Asset Capture'!P7:P1000,"Pass") -> 0
A11: Drafted | B11: =COUNTIF('04 Asset Capture'!T7:T1000,"Drafted") -> 0 | D11: Fail | E11: =COUNTIF('04 Asset Capture'!P7:P1000,"Fail") -> 0
A12: In review | B12: =COUNTIF('04 Asset Capture'!T7:T1000,"In review") -> 0 | D12: Partial | E12: =COUNTIF('04 Asset Capture'!P7:P1000,"Partial") -> 0
A13: Approved | B13: =COUNTIF('04 Asset Capture'!T7:T1000,"Approved") -> 0 | D13: N/A | E13: =COUNTIF('04 Asset Capture'!P7:P1000,"N/A") -> 0
A14: Live | B14: =COUNTIF('04 Asset Capture'!T7:T1000,"Live") -> 0
A15: Needs update | B15: =COUNTIF('04 Asset Capture'!T7:T1000,"Needs update") -> 0
A16: Retired | B16: =COUNTIF('04 Asset Capture'!T7:T1000,"Retired") -> 0
A18: PER-COURSE ROLLUP
A19: Course Code | B19: Assets | C19: With URL | D19: Outcomes | E19: Modules | F19: Assessments | G19: RSI
A20: ='01 Course Information'!B6 -> COURSE 101 | B20: =IF(A20="","",COUNTIF('04 Asset Capture'!B7:B1000,A20)) -> 0 | C20: =IF(A20="","",COUNTIFS('04 Asset Capture'!B7:B1000,A20,'04 Asset Capture'!G7:G1000,"<>")) -> 0 | D20: =IF(A20="","",COUNTIF('03 Learning Outcomes'!B7:B1000,A20)) -> 0 | E20: =IF(A20="","",COUNTIF('06 Module Builder'!B7:B1000,A20)) -> 0 | F20: =IF(A20="","",COUNTIF('07 Assessments'!B7:B1000,A20)) -> 0 | G20: =IF(A20="","",COUNTIF('10 RSI'!B7:B1000,A20)) -> 0
A21: ='01 Course Information'!B7 -> 0 | B21: =IF(A21="","",COUNTIF('04 Asset Capture'!B7:B1000,A21)) | C21: =IF(A21="","",COUNTIFS('04 Asset Capture'!B7:B1000,A21,'04 Asset Capture'!G7:G1000,"<>")) | D21: =IF(A21="","",COUNTIF('03 Learning Outcomes'!B7:B1000,A21)) | E21: =IF(A21="","",COUNTIF('06 Module Builder'!B7:B1000,A21)) | F21: =IF(A21="","",COUNTIF('07 Assessments'!B7:B1000,A21)) | G21: =IF(A21="","",COUNTIF('10 RSI'!B7:B1000,A21))
A22: ='01 Course Information'!B8 -> 0 | B22: =IF(A22="","",COUNTIF('04 Asset Capture'!B7:B1000,A22)) | C22: =IF(A22="","",COUNTIFS('04 Asset Capture'!B7:B1000,A22,'04 Asset Capture'!G7:G1000,"<>")) | D22: =IF(A22="","",COUNTIF('03 Learning Outcomes'!B7:B1000,A22)) | E22: =IF(A22="","",COUNTIF('06 Module Builder'!B7:B1000,A22)) | F22: =IF(A22="","",COUNTIF('07 Assessments'!B7:B1000,A22)) | G22: =IF(A22="","",COUNTIF('10 RSI'!B7:B1000,A22))
A23: ='01 Course Information'!B9 -> 0 | B23: =IF(A23="","",COUNTIF('04 Asset Capture'!B7:B1000,A23)) | C23: =IF(A23="","",COUNTIFS('04 Asset Capture'!B7:B1000,A23,'04 Asset Capture'!G7:G1000,"<>")) | D23: =IF(A23="","",COUNTIF('03 Learning Outcomes'!B7:B1000,A23)) | E23: =IF(A23="","",COUNTIF('06 Module Builder'!B7:B1000,A23)) | F23: =IF(A23="","",COUNTIF('07 Assessments'!B7:B1000,A23)) | G23: =IF(A23="","",COUNTIF('10 RSI'!B7:B1000,A23))
A24: ='01 Course Information'!B10 -> 0 | B24: =IF(A24="","",COUNTIF('04 Asset Capture'!B7:B1000,A24)) | C24: =IF(A24="","",COUNTIFS('04 Asset Capture'!B7:B1000,A24,'04 Asset Capture'!G7:G1000,"<>")) | D24: =IF(A24="","",COUNTIF('03 Learning Outcomes'!B7:B1000,A24)) | E24: =IF(A24="","",COUNTIF('06 Module Builder'!B7:B1000,A24)) | F24: =IF(A24="","",COUNTIF('07 Assessments'!B7:B1000,A24)) | G24: =IF(A24="","",COUNTIF('10 RSI'!B7:B1000,A24))
A25: ='01 Course Information'!B11 -> 0 | B25: =IF(A25="","",COUNTIF('04 Asset Capture'!B7:B1000,A25)) | C25: =IF(A25="","",COUNTIFS('04 Asset Capture'!B7:B1000,A25,'04 Asset Capture'!G7:G1000,"<>")) | D25: =IF(A25="","",COUNTIF('03 Learning Outcomes'!B7:B1000,A25)) | E25: =IF(A25="","",COUNTIF('06 Module Builder'!B7:B1000,A25)) | F25: =IF(A25="","",COUNTIF('07 Assessments'!B7:B1000,A25)) | G25: =IF(A25="","",COUNTIF('10 RSI'!B7:B1000,A25))
A26: ='01 Course Information'!B12 -> 0 | B26: =IF(A26="","",COUNTIF('04 Asset Capture'!B7:B1000,A26)) | C26: =IF(A26="","",COUNTIFS('04 Asset Capture'!B7:B1000,A26,'04 Asset Capture'!G7:G1000,"<>")) | D26: =IF(A26="","",COUNTIF('03 Learning Outcomes'!B7:B1000,A26)) | E26: =IF(A26="","",COUNTIF('06 Module Builder'!B7:B1000,A26)) | F26: =IF(A26="","",COUNTIF('07 Assessments'!B7:B1000,A26)) | G26: =IF(A26="","",COUNTIF('10 RSI'!B7:B1000,A26))
A27: ='01 Course Information'!B13 -> 0 | B27: =IF(A27="","",COUNTIF('04 Asset Capture'!B7:B1000,A27)) | C27: =IF(A27="","",COUNTIFS('04 Asset Capture'!B7:B1000,A27,'04 Asset Capture'!G7:G1000,"<>")) | D27: =IF(A27="","",COUNTIF('03 Learning Outcomes'!B7:B1000,A27)) | E27: =IF(A27="","",COUNTIF('06 Module Builder'!B7:B1000,A27)) | F27: =IF(A27="","",COUNTIF('07 Assessments'!B7:B1000,A27)) | G27: =IF(A27="","",COUNTIF('10 RSI'!B7:B1000,A27))
A28: ='01 Course Information'!B14 -> 0 | B28: =IF(A28="","",COUNTIF('04 Asset Capture'!B7:B1000,A28)) | C28: =IF(A28="","",COUNTIFS('04 Asset Capture'!B7:B1000,A28,'04 Asset Capture'!G7:G1000,"<>")) | D28: =IF(A28="","",COUNTIF('03 Learning Outcomes'!B7:B1000,A28)) | E28: =IF(A28="","",COUNTIF('06 Module Builder'!B7:B1000,A28)) | F28: =IF(A28="","",COUNTIF('07 Assessments'!B7:B1000,A28)) | G28: =IF(A28="","",COUNTIF('10 RSI'!B7:B1000,A28))
A29: ='01 Course Information'!B15 -> 0 | B29: =IF(A29="","",COUNTIF('04 Asset Capture'!B7:B1000,A29)) | C29: =IF(A29="","",COUNTIFS('04 Asset Capture'!B7:B1000,A29,'04 Asset Capture'!G7:G1000,"<>")) | D29: =IF(A29="","",COUNTIF('03 Learning Outcomes'!B7:B1000,A29)) | E29: =IF(A29="","",COUNTIF('06 Module Builder'!B7:B1000,A29)) | F29: =IF(A29="","",COUNTIF('07 Assessments'!B7:B1000,A29)) | G29: =IF(A29="","",COUNTIF('10 RSI'!B7:B1000,A29))

Sheet 01 Course Information
A1: TAB 01 · START HERE
A2: Course Information
A3: One row per course. The dashboard, dropdowns, and reports all key off the Course Code you enter here.
A4: Course ID | B4: Course Code | C4: Course Title | D4: Institution | E4: Term | F4: Modality | G4: Delivery Notes | H4: Credit Hours | I4: Enrollment Cap | J4: Start Date | K4: End Date | L4: LMS Shell URL | M4: Public Site / Kajabi URL | N4: Repository | O4: Course Description | P4: Status | Q4: Last Updated | R4: Owner / Instructor
A5: Auto. C01, C02… or your own scheme | B5: e.g., BIO 304, NURS 210, HIST 101 | C5: Full course title as it appears in catalog | D5: College / university name | E5: e.g., Fall 2026, Summer 2026, 8-Week B | F5: Pick from list | G5: Free text. TBL? Hybrid pattern? Sync hours? | H5: Number | I5: Max students | J5: YYYY-MM-DD | K5: YYYY-MM-DD | L5: Canvas / Blackboard / Moodle URL | M5: If you publish externally | N5: GitHub or Google Drive root | O5: 1–2 sentence catalog description | P5: Pick from list | Q5: YYYY-MM-DD | R5: Your name as it appears to students
A6: C01 | B6: COURSE 101 | C6: Example Course Title | D6: Your College | E6: Fall 2026 | F6: In-person | G6: Delete this row after reading. Example only. | H6: 3 | I6: 30 | J6: 2026-08-25 | K6: 2026-12-15 | O6: Short description here. | P6: Active | Q6: 2026-05-29 | R6: Faculty Name

Sheet 02 Faculty Brand Sheet
A1: TAB 02
A2: Faculty Brand Sheet
A3: Your instructional DNA. Claude (or any AI collaborator) reads this to match your voice and pedagogy when generating materials.
A4: Section | B4: Field | C4: Your Answer | D4: Notes / Examples
A5: Locked. Do not edit. | B5: Locked. Do not edit. | C5: Type your answer here. | D5: Optional. Add references or constraints.
A6: 1 Faculty Identity | B6: Faculty name | D6: Name as you want it to appear in student-facing materials
A7: 1 Faculty Identity | B7: Credentials (internal use only) | D7: Your degrees/licenses. Internal only. Not auto-appended to student copy.
A8: 1 Faculty Identity | B8: Discipline | D8: e.g., Anatomy, Statistics, Composition
A9: 1 Faculty Identity | B9: Institution type | D9: Community college / 4-year / Graduate / Other
A10: 1 Faculty Identity | B10: Years teaching
A11: 1 Faculty Identity | B11: Clinical or professional experience | D11: Years in industry, practice, or research
A12: 1 Faculty Identity | B12: Areas of expertise | D12: Comma-separated
A13: 2 Teaching Philosophy | B13: What do you believe about learning? | D13: One paragraph
A14: 2 Teaching Philosophy | B14: What should students experience in your course?
A15: 2 Teaching Philosophy | B15: What frustrates you about traditional teaching?
A16: 2 Teaching Philosophy | B16: What does student success look like?
A17: 3 Student Population | B17: Student type | D17: e.g., pre-nursing, gen-ed, majors
A18: 3 Student Population | B18: Academic level | D18: First-year / transfer / graduate
A19: 3 Student Population | B19: Prerequisites | D19: List required coursework
A20: 3 Student Population | B20: Common challenges | D20: What do students typically struggle with?
A21: 3 Student Population | B21: Career goals | D21: Where do they go after this course?
A22: 4 Course Design | B22: Preferred pedagogy | D22: TBL, Case-Based, Flipped, Lecture, Mastery, etc.
A23: 4 Course Design | B23: Preferred weekly rhythm | D23: e.g., M/W/F lecture, T/Th lab
A24: 4 Course Design | B24: Preferred learning activities | D24: Top 3
A25: 5 Content Preferences | B25: Level of detail | D25: Survey / standard / deep dive
A26: 5 Content Preferences | B26: Use of clinical/real-world correlations
A27: 5 Content Preferences | B27: Use of visuals | D27: High / moderate / low. Any specific style?
A28: 5 Content Preferences | B28: Use of storytelling
A29: 5 Content Preferences | B29: Use of examples
A30: 6 Assessment | B30: What should assessments measure?
A31: 6 Assessment | B31: Preferred assessment types | D31: Quiz, project, drawing, RAT, etc.
A32: 6 Assessment | B32: AI-resistant strategies | D32: e.g., in-class drawing, oral defense
A33: 6 Assessment | B33: Authentic assessment preferences
A34: 7 Communication | B34: Tone | D34: Warm / formal / direct / playful
A35: 7 Communication | B35: Formality level
A36: 7 Communication | B36: Feedback style | D36: Brief / detailed / rubric-anchored
A37: 7 Communication | B37: Student support style | D37: Office-hours model, response time, etc.
A38: 8 Visual Style | B38: Color preferences | D38: Hex codes or palette name
A39: 8 Visual Style | B39: Typography preferences | D39: Display + body fonts
A40: 8 Visual Style | B40: Layout preferences
...

Sheet 03 Learning Outcomes
A1: TAB 03
A2: Learning Outcomes
A3: Anchor everything else. Each outcome gets an ID you'll reference in Modules, Assessments, and Assets.
A4: Outcome ID | B4: Course Code | C4: Module/Unit | D4: Outcome Statement | E4: Bloom Level | F4: DOK Level | G4: Aligned Assessment IDs | H4: Aligned Module IDs | I4: Status | J4: Notes
A5: LO01, LO02… or course-prefixed (BIO304-LO01) | B5: Pick from list | C5: Where the outcome lives | D5: 'Students will be able to…' (one verb, one object) | E5: Pick from list | F5: Pick from list | G5: Comma-separated assessment IDs | H5: Comma-separated module IDs | I5: Pick from list | J5: Anything that doesn't fit elsewhere
A6: LO01 | B6: COURSE 101 | C6: Module 1 | D6: Students will identify the four phases of mitosis. | E6: Remember | F6: 1 | G6: A01 | H6: M01 | I6: In progress | J6: Example only. Delete.

Sheet 04 Asset Capture
A1: TAB 04 · LINK LIBRARY
A2: Asset Capture — Master Link & Material Library
A3: Every video, reading, tool, slide deck, rubric, simulator. One row per asset. The dashboard counts here.
A4: Asset ID | B4: Course Code | C4: Module | D4: Week | E4: Asset Type | F4: Title | G4: URL / Path | H4: Source | I4: Repo Path | J4: Live URL | K4: File Format | L4: Outcome IDs | M4: Assessment IDs | N4: DOK Level | O4: RSI Tag | P4: Accessibility Status | Q4: WCAG Audit Date | R4: iframe Height-Sender | S4: target=_top Confirmed | T4: Status | U4: Owner | V4: Date Added | W4: Last Reviewed | X4: Notes
A5: A001, A002… auto-increment | B5: Pick from list | C5: Module ID or name | D5: Week number | E5: Pick from list | F5: Display title (what students see) | G5: PASTE LINK HERE | H5: Pick from list (where it lives) | I5: If in a repo: path/from/root.html | J5: Public URL if different from URL/Path | K5: mp4, pdf, html, docx, etc. | L5: Comma-separated outcome IDs | M5: Comma-separated assessment IDs | N5: Pick from list | O5: Pick from list | P5: Pick from list | Q5: YYYY-MM-DD | R5: Yes/No/N/A (HTML embeds only) | S5: Yes/No/N/A (HTML embeds only) | T5: Pick from list | U5: Who built/owns it | V5: YYYY-MM-DD | W5: YYYY-MM-DD | X5: Free text
A6: A001 | B6: COURSE 101 | C6: M01 | D6: 1 | E6: Video | F6: Intro to the cell | G6: https://example.com/intro-cell | H6: External | K6: mp4 | L6: LO01 | N6: 2 | O6: Direct Instruction | P6: Pass | Q6: 2026-05-29 | R6: N/A | S6: N/A | T6: Live | U6: Faculty | V6: 2026-05-29 | W6: 2026-05-29 | X6: Example only. Delete.

Sheet 05 Schedule & Pacing
A1: TAB 05
A2: Schedule & Pacing
A3: One row per session or pre-work block. Pair with Module Builder to anchor week-by-week flow.
A4: Course Code | B4: Week | C4: Date | D4: Day of Week | E4: Module/Unit | F4: Topics | G4: Sync/Async | H4: Contact Hours | I4: Pre-Class Asset IDs | J4: In-Class Activity IDs | K4: Post-Class Asset IDs | L4: Deliverables Due | M4: Notes
A5: Pick from list | B5: Number | C5: YYYY-MM-DD | D5: Mon/Tue/Wed/Thu/Fri/Sat/Sun | E5: Module ID or name | F5: Comma-separated topic titles | G5: Pick from list | H5: Hours of student contact | I5: Asset IDs students do before class | J5: Asset IDs used live | K5: Asset IDs assigned after | L5: What's due that day | M5: Free text
A6: COURSE 101 | B6: 1 | C6: 2026-08-25 | D6: Mon | E6: M01 | F6: Levels of organization | G6: In-person | H6: 1.5 | I6: A001 | L6: Reading reflection | M6: Example only. Delete.

Sheet 06 Module Builder
A1: TAB 06
A2: Module Builder
A3: The structural unit. Each module ties outcomes, assets, activities, and assessments together.
A4: Module ID | B4: Course Code | C4: Module Title | D4: Sequence # | E4: Outcome IDs | F4: Pre-Class Asset IDs | G4: In-Class Activity IDs | H4: Post-Class Asset IDs | I4: Assessment IDs | J4: RSI Touchpoints | K4: Engagement Tactics | L4: Estimated Hours | M4: Status | N4: Notes
A5: M01, M02… | B5: Pick from list | C5: What this module is about | D5: 1, 2, 3… | E5: Comma-separated outcome IDs | F5: Asset IDs | G5: Asset IDs (live class) | H5: Asset IDs (after class) | I5: Assessment IDs | J5: Comma-separated RSI categories | K5: Comma-separated engagement tactics | L5: Total student time | M5: Pick from list | N5: Free text
A6: M01 | B6: COURSE 101 | C6: Foundations | D6: 1 | E6: LO01 | F6: A001 | I6: A01 | J6: Direct Instruction, Feedback | K6: Active learning | L6: 3 | M6: In progress | N6: Example only. Delete.

Sheet 07 Assessments
A1: TAB 07
A2: Assessments
A3: Every graded touchpoint. Tag each one with the outcomes it measures and its AI-resistance strategy.
A4: Assessment ID | B4: Course Code | C4: Module | D4: Assessment Type | E4: Title | F4: Weight (%) | G4: DOK Level | H4: AI-Resistant Strategy | I4: Rubric URL | J4: Outcome IDs | K4: Due Window | L4: Status | M4: Owner | N4: Notes
A5: A01, A02… | B5: Pick from list | C5: Module ID | D5: Pick from list | E5: What students see | F5: 0–100 | G5: Pick from list | H5: How you'll keep it authentic (in-class, drawing, oral, etc.) | I5: Link to rubric | J5: Comma-separated outcome IDs | K5: When it opens/closes | L5: Pick from list | M5: Faculty member | N5: Free text
A6: A01 | B6: COURSE 101 | C6: M01 | D6: Quiz | E6: Module 1 readiness check | F6: 5 | G6: 2 | H6: Proctored in-class | J6: LO01 | K6: Week 1 | L6: Drafted | M6: Faculty | N6: Example only. Delete.

Sheet 08 Engagement
A1: TAB 08
A2: Engagement Strategy
A3: Tactics that pull students into the material. Tie them to specific modules and outcomes.
A4: Engagement ID | B4: Course Code | C4: Module | D4: Tactic | E4: Type | F4: Frequency | G4: Asset ID | H4: Evidence URL | I4: Outcome Tie-In | J4: Status | K4: Notes
A5: E01, E02… | B5: Pick from list | C5: Module ID | D5: Name the tactic | E5: Pick from list | F5: Per session / weekly / one-time | G5: Tool/asset ID if any | H5: Where evidence lives | I5: Outcome ID(s) | J5: Pick from list | K5: Free text
A6: E01 | B6: COURSE 101 | C6: M01 | D6: Think-pair-share on case | E6: Active learning | F6: Per session | I6: LO01 | J6: In progress | K6: Example only. Delete.

Sheet 09 Accessibility
A1: TAB 09
A2: Accessibility — WCAG 2.2 Audit
A3: One row per criterion checked, per asset. Aim for AA floor, AAA where achievable.
A4: Audit ID | B4: Course Code | C4: Asset ID | D4: File / Page | E4: WCAG Criterion | F4: Target Level | G4: Status | H4: Contrast Pair | I4: Contrast Ratio | J4: Keyboard Verified | K4: Screen Reader Verified | L4: Captions | M4: Alt Text | N4: Headings | O4: Audit Date | P4: Reviewer | Q4: Remediation Plan | R4: Notes
A5: AU001… | B5: Pick from list | C5: Asset ID | D5: File name or URL | E5: e.g., 1.4.3 Contrast | F5: Pick from list | G5: Pick from list | H5: e.g., navy on white | I5: e.g., 7.2:1 | J5: Pick from list | K5: Pick from list | L5: Pick from list | M5: Pick from list | N5: Pick from list | O5: YYYY-MM-DD | P5: Reviewer name | Q5: What needs fixing and by when | R5: Free text
A6: AU001 | B6: COURSE 101 | C6: A001 | D6: intro-cell.html | E6: 1.4.3 Contrast | F6: AA | G6: Pass | H6: navy on off-white | I6: 7.2:1 | J6: Yes | K6: Yes | L6: Yes | M6: Yes | N6: Yes | O6: 2026-05-29 | P6: Reviewer | R6: Example only. Delete.

Sheet 10 RSI
A1: TAB 10
A2: Regular & Substantive Interaction (RSI)
A3: Evidence that the instructor is regularly and substantively present. Required for online and async modalities.
A4: RSI ID | B4: Course Code | C4: Module | D4: Week | E4: RSI Category | F4: Activity | G4: Frequency | H4: Evidence URL | I4: Owner | J4: Status | K4: Notes
A5: R001… | B5: Pick from list | C5: Module ID | D5: Week # | E5: Pick from list | F5: What you do | G5: Daily / weekly / per-module | H5: Link to evidence | I5: Who runs it | J5: Pick from list | K5: Free text
A6: R001 | B6: COURSE 101 | C6: M01 | D6: 1 | E6: Instructor Presence | F6: Weekly check-in announcement | G6: Weekly | I6: Faculty | J6: In progress | K6: Example only. Delete.

Sheet 11 Quality Assurance
A1: TAB 11
A2: Quality Assurance
A3: Pre-launch checklist. Each row is a check you've run against a course or asset.
A4: QA ID | B4: Course Code | C4: Asset ID | D4: Check | E4: Standard | F4: Status | G4: Date | H4: Reviewer | I4: Issue Found | J4: Resolution | K4: Notes
A5: QA001… | B5: Pick from list | C5: Asset ID if applicable | D5: What you checked | E5: What 'pass' looks like | F5: Pick from list | G5: YYYY-MM-DD | H5: Reviewer name | I5: If failed: what's wrong | J5: If failed: what's the fix | K5: Free text
A6: QA001 | B6: COURSE 101 | D6: Outcome alignment | E6: Every asset maps to ≥1 outcome | F6: Pass | G6: 2026-05-29 | H6: Reviewer | K6: Example only. Delete.
A7: QA002 | D7: Brand alignment | E7: Colors, fonts, tone match Brand Sheet
A8: QA003 | D8: Accessibility audit | E8: All WCAG criteria on tab 09 marked Pass or Waived
A9: QA004 | D9: Link health | E9: Every URL in Asset Capture returns 200
A10: QA005 | D10: Outcome coverage | E10: Every outcome has ≥1 asset + ≥1 assessment
A11: QA006 | D11: RSI evidence | E11: ≥1 RSI entry per module
A12: QA007 | D12: Embed readiness | E12: HTML embeds tested in LMS iframe
A13: QA008 | D13: Compliance notes filed | E13: compliance-notes.md saved in project folder

Sheet 12 Launch
A1: TAB 12
A2: Launch Readiness
A3: Final mile. Sign-offs and dry-run before students arrive.
A4: Task ID | B4: Course Code | C4: Task | D4: Owner | E4: Due Date | F4: Dependencies | G4: Status | H4: Evidence / URL | I4: Notes
A5: L001… | B5: Pick from list | C5: What needs to happen | D5: Who owns it | E5: YYYY-MM-DD | F5: Task IDs that must finish first | G5: Pick from list | H5: Link to proof | I5: Free text
A6: L001 | C6: Course blueprint signed off
A7: L002 | C7: Faculty Brand Sheet locked
A8: L003 | C8: All outcomes mapped to assets + assessments
A9: L004 | C9: Accessibility audit passed
A10: L005 | C10: RSI evidence matrix complete
A11: L006 | C11: Compliance notes filed
A12: L007 | C12: LMS shell populated
A13: L008 | C13: Embeds tested in LMS
A14: L009 | C14: Syllabus byline + contact info reviewed
A15: L010 | C15: Launch dry-run completed

Sheet Lookups
A1: Courses | B1: Status_Asset | C1: Status_Course | D1: Status_Generic | E1: Status_QA | F1: Status_A11y | G1: Asset_Type | H1: Source | I1: Modality | J1: Bloom | K1: DOK | L1: RSI_Category | M1: WCAG_Target | N1: YesNo | O1: Assessment_Type | P1: Engagement_Type | Q1: DoW
A2: COURSE 101 | B2: Planned | C2: Active | D2: Not started | E2: Pending | F2: Pass | G2: Video | H2: LMS-hosted | I2: In-person | J2: Remember | K2: 1 | L2: Instructor Presence | M2: AA | N2: Yes | O2: Quiz | P2: Active learning | Q2: Mon
A3: COURSE 102 | B3: Drafted | C3: Drafting | D3: In progress | E3: Pass | F3: Fail | G3: Reading | H3: GitHub Pages | I3: Online | J3: Understand | K3: 2 | L3: Direct Instruction | M3: AAA | N3: No | O3: Test | P3: Drawing-based | Q3: Tue
B4: In review | C4: Skeleton | D4: Blocked | E4: Fail | F4: Partial | G4: Slide deck | H4: Public site | I4: Hybrid | J4: Apply | K4: 3 | L4: Guided Facilitation | N4: N/A | O4: Midterm | P4: Case study | Q4: Wed
B5: Approved | C5: Paused | D5: Complete | E5: Waived | F5: N/A | G5: Worksheet | H5: YouTube | I5: HyFlex | J5: Analyze | K5: 4 | L5: Feedback | O5: Final | P5: Simulation | Q5: Thu
B6: Live | C6: Archived | D6: Skipped | G6: Rubric | H6: Vimeo | I6: Async | J6: Evaluate | L6: Communication Plan | O6: iRAT | P6: Discussion | Q6: Fri
B7: Needs update | G7: HTML tool | H7: Library DB | I7: Sync | J7: Create | L7: Evidence | O7: tRAT | P7: Peer review | Q7: Sat
B8: Retired | G8: Simulator | H8: Publisher (OpenStax etc.) | O8: Application activity | P8: Polling | Q8: Sun
G9: Quiz | H9: External | O9: Lab exam | P9: Game
G10: Lab activity | H10: Local | O10: Project | P10: Reflection
G11: Discussion | H11: Other | O11: Drawing synthesis | P11: Office hours
G12: Drawing prompt | O12: Case analysis | P12: Other
G13: Case study | O13: Discussion
G14: External link | O14: Reflection
G15: Document (PDF) | O15: Presentation
G16: Document (DOCX) | O16: Other
G17: Other
